Workbook

Sheet Log Book
A1: Flying | E1: =SUM(M1:T1) -> 26.656944 | F1: Count | G1: =COUNT(A6:A65536) -> 592 | J1: Time: | K1: =SUM(M1:T1) -> 26.656944 | M1: =SUM(M6:M65536) -> 11.323611 | N1: =SUM(N6:N65536) -> 7.1097222 | O1: =SUM(O6:O65536) -> 4.8708333 | P1: =SUM(P6:P65536) -> 2.8541667 | Q1: =SUM(Q6:Q65536) -> 0.22708333 | R1: =SUM(R6:R65536) -> 0.13541667 | S1: =SUM(S6:S65536) -> 0.13611111 | T1: =SUM(T6:T65536) -> 0 | ... W1: =SUM(W6:W65536) -> 19.8
A2: Sim | E2: =W1/24 -> 0.825 | J2: Count: | M2: =COUNTIF(M6:M65536, ">0") -> 258 | N2: =COUNTIF(N6:N65536, ">0") -> 170 | O2: =COUNTIF(O6:O65536, ">0") -> 94 | P2: =COUNTIF(P6:P65536, ">0") -> 47 | Q2: =COUNTIF(Q6:Q65536, ">0") -> 5 | R2: =COUNTIF(R6:R65536, ">0") -> 3 | S2: =COUNTIF(S6:S65536, ">0") -> 6 | T2: =COUNTIF(T6:T65536, ">0") -> 0 | ... W2: =COUNTIF(W6:W65536, ">0") -> 14
A4: Total | E4: =E2+E1 -> 27.481944 | M4: Single Engine | O4: Multi Engine | Q4: Single Engine | S4: Multi Engine
A5: Date | B5: Ttype | C5: xxx | D5: xxy | E5: Type | F5: Reg | G5: Captain | H5: Operating Capacity | I5: From | J5: To | K5: Depart | L5: Arrival | M5: In Command | N5: Dual | O5: In Command | P5: Dual | Q5: In Command | R5: Dual | S5: In Command | T5: Dual | U5: Instrument Flying | V5: Instructor | W5: Simulated | X5: Flight Time | Y5: Comments
A6: 35655 | B6: =VLOOKUP(F6, Aircraft!A$2:C$99, 2, FALSE) -> C152 | C6: =VLOOKUP(F6, Aircraft!A$2:C$99, 3, FALSE) -> S | D6: =IF(ISNA(C6), "", C6) -> S | E6: =IF(ISNA(B6), "", B6) -> C152 | F6: GLSMI | G6: Kingshott | H6: =IF(UPPER(G6)<>"SELF","PUT","P1") -> PUT | I6: EGKA | J6: EGKA | K6: 0.79166667 | L6: 0.82291667 | M6: =IF(AND(H6="P1", C6="S"), L6-K6, 0) -> 0 | N6: =IF(AND(H6="PUT", C6="S"), L6-K6, 0) -> 0.03125 | X6: =SUM(M6:S6) -> 0.03125 | Y6: Ex4.1, Ex3
A7: 35680 | B7: =VLOOKUP(F7, Aircraft!A$2:C$99, 2, FALSE) -> C152 | C7: =VLOOKUP(F7, Aircraft!A$2:C$99, 3, FALSE) -> S | D7: =IF(ISNA(C7), "", C7) -> S | E7: =IF(ISNA(B7), "", B7) -> C152 | F7: GBOIN | G7: Kingshott | H7: =IF(UPPER(G7)<>"SELF","PUT","P1") -> PUT | I7: EGKA | J7: EGKA | K7: 0.47916667 | L7: 0.53472222 | M7: =IF(AND(H7="P1", C7="S"), L7-K7, 0) -> 0 | N7: =IF(AND(H7="PUT", C7="S"), L7-K7, 0) -> 0.055555556 | X7: =SUM(M7:S7) -> 0.055555556 | Y7: Ex4.2, 6, 1, 2
A8: 35680 | B8: =VLOOKUP(F8, Aircraft!A$2:C$99, 2, FALSE) -> C152 | C8: =VLOOKUP(F8, Aircraft!A$2:C$99, 3, FALSE) -> S | D8: =IF(ISNA(C8), "", C8) -> S | E8: =IF(ISNA(B8), "", B8) -> C152 | F8: GBPTF | G8: Kingshott | H8: =IF(UPPER(G8)<>"SELF","PUT","P1") -> PUT | I8: EGKA | J8: EGKA | K8: 0.75694444 | L8: 0.80902778 | M8: =IF(AND(H8="P1", C8="S"), L8-K8, 0) -> 0 | N8: =IF(AND(H8="PUT", C8="S"), L8-K8, 0) -> 0.052083333 | X8: =SUM(M8:S8) -> 0.052083333 | Y8: Ex6.2, 7, 8, 5E
A9: 35687 | B9: =VLOOKUP(F9, Aircraft!A$2:C$99, 2, FALSE) -> C152 | C9: =VLOOKUP(F9, Aircraft!A$2:C$99, 3, FALSE) -> S | D9: =IF(ISNA(C9), "", C9) -> S | E9: =IF(ISNA(B9), "", B9) -> C152 | F9: GLSMI | G9: Kingshott | H9: =IF(UPPER(G9)<>"SELF",IF(G9<>"", "PUT", ""),"P1") -> PUT | I9: EGKA | J9: EGKA | K9: 0.75694444 | L9: 0.80555556 | M9: =IF(AND(H9="P1", D9="S"), L9-K9, 0) -> 0 | N9: =IF(AND(H9="PUT", D9="S"), L9-K9, 0) -> 0.048611111 | X9: =SUM(M9:S9) -> 0.048611111 | Y9: Ex8
A10: 35701 | B10: =VLOOKUP(F10, Aircraft!A$2:C$99, 2, FALSE) -> C152 | C10: =VLOOKUP(F10, Aircraft!A$2:C$99, 3, FALSE) -> S | D10: =IF(ISNA(C10), "", C10) -> S | E10: =IF(ISNA(B10), "", B10) -> C152 | F10: GBPTF | G10: Kingshott | H10: =IF(UPPER(G10)<>"SELF",IF(G10<>"", "PUT", ""),"P1") -> PUT | I10: EGKA | J10: EGKA | K10: 0.59027778 | L10: 0.63888889 | M10: =IF(AND(H10="P1", D10="S"), L10-K10, 0) -> 0 | N10: =IF(AND(H10="PUT", D10="S"), L10-K10, 0) -> 0.048611111 | X10: =SUM(M10:S10) -> 0.048611111 | Y10: Ex9
A11: 35727 | B11: =VLOOKUP(F11, Aircraft!A$2:C$99, 2, FALSE) -> C152 | C11: =VLOOKUP(F11, Aircraft!A$2:C$99, 3, FALSE) -> S | D11: =IF(ISNA(C11), "", C11) -> S | E11: =IF(ISNA(B11), "", B11) -> C152 | F11: GLSMI | G11: Kingshott | H11: =IF(UPPER(G11)<>"SELF",IF(G11<>"", "PUT", ""),"P1") -> PUT | I11: EGKA | J11: EGKA | K11: 0.60416667 | L11: 0.64583333 | M11: =IF(AND(H11="P1", D11="S"), L11-K11, 0) -> 0 | N11: =IF(AND(H11="PUT", D11="S"), L11-K11, 0) -> 0.041666667 | X11: =SUM(M11:S11) -> 0.041666667 | Y11: Revision Ex 5
A12: 35728 | B12: =VLOOKUP(F12, Aircraft!A$2:C$99, 2, FALSE) -> C152 | C12: =VLOOKUP(F12, Aircraft!A$2:C$99, 3, FALSE) -> S | D12: =IF(ISNA(C12), "", C12) -> S | E12: =IF(ISNA(B12), "", B12) -> C152 | F12: GBPTF | G12: Kingshott | H12: =IF(UPPER(G12)<>"SELF",IF(G12<>"", "PUT", ""),"P1") -> PUT | I12: EGKA | J12: EGKA | K12: 0.44097222 | L12: 0.48263889 | M12: =IF(AND(H12="P1", D12="S"), L12-K12, 0) -> 0 | N12: =IF(AND(H12="PUT", D12="S"), L12-K12, 0) -> 0.041666667 | X12: =SUM(M12:S12) -> 0.041666667 | Y12: Ex 9
A13: 35729 | B13: =VLOOKUP(F13, Aircraft!A$2:C$99, 2, FALSE) -> PA28 | C13: =VLOOKUP(F13, Aircraft!A$2:C$99, 3, FALSE) -> S | D13: =IF(ISNA(C13), "", C13) -> S | E13: =IF(ISNA(B13), "", B13) -> PA28 | F13: GBNNY | G13: Kingshott | H13: =IF(UPPER(G13)<>"SELF",IF(G13<>"", "PUT", ""),"P1") -> PUT | I13: EGKA | J13: EGKA | K13: 0.46180556 | L13: 0.50694444 | M13: =IF(AND(H13="P1", D13="S"), L13-K13, 0) -> 0 | N13: =IF(AND(H13="PUT", D13="S"), L13-K13, 0) -> 0.045138889 | X13: =SUM(M13:S13) -> 0.045138889 | Y13: Ex 10, Revision
A15: 35833 | B15: =VLOOKUP(F15, Aircraft!A$2:C$99, 2, FALSE) -> PA28 | C15: =VLOOKUP(F15, Aircraft!A$2:C$99, 3, FALSE) -> S | D15: =IF(ISNA(C15), "", C15) -> S | E15: =IF(ISNA(B15), "", B15) -> PA28 | F15: GBIEY | G15: Kingshott | H15: =IF(UPPER(G15)<>"SELF",IF(G15<>"", "PUT", ""),"P1") -> PUT | I15: EGKA | J15: EGKA | K15: 0.41666667 | L15: 0.45833333 | M15: =IF(AND(H15="P1", D15="S"), L15-K15, 0) -> 0 | N15: =IF(AND(H15="PUT", D15="S"), L15-K15, 0) -> 0.041666667 | X15: =SUM(M15:S15) -> 0.041666667 | Y15: Revision
A16: 35833 | B16: =VLOOKUP(F16, Aircraft!A$2:C$99, 2, FALSE) -> PA28 | C16: =VLOOKUP(F16, Aircraft!A$2:C$99, 3, FALSE) -> S | D16: =IF(ISNA(C16), "", C16) -> S | E16: =IF(ISNA(B16), "", B16) -> PA28 | F16: GBIEY | G16: Kingshott | H16: =IF(UPPER(G16)<>"SELF",IF(G16<>"", "PUT", ""),"P1") -> PUT | I16: EGKA | J16: EGKA | K16: 0.66666667 | L16: 0.70486111 | M16: =IF(AND(H16="P1", D16="S"), L16-K16, 0) -> 0 | N16: =IF(AND(H16="PUT", D16="S"), L16-K16, 0) -> 0.038194444 | X16: =SUM(M16:S16) -> 0.038194444 | Y16: Ex10b, (0:30) - Signed
A17: 35847 | B17: =VLOOKUP(F17, Aircraft!A$2:C$99, 2, FALSE) -> PA28 | C17: =VLOOKUP(F17, Aircraft!A$2:C$99, 3, FALSE) -> S | D17: =IF(ISNA(C17), "", C17) -> S | E17: =IF(ISNA(B17), "", B17) -> PA28 | F17: GBNNY | G17: Kingshott | H17: =IF(UPPER(G17)<>"SELF",IF(G17<>"", "PUT", ""),"P1") -> PUT | I17: EGKA | J17: EGKA | K17: 0.64236111 | L17: 0.65277778 | M17: =IF(AND(H17="P1", D17="S"), L17-K17, 0) -> 0 | N17: =IF(AND(H17="PUT", D17="S"), L17-K17, 0) -> 0.010416667 | X17: =SUM(M17:S17) -> 0.010416667 | Y17: Ex 19, Aborted smoke in Cockpit
A18: 35848 | B18: =VLOOKUP(F18, Aircraft!A$2:C$99, 2, FALSE) -> PA28 | C18: =VLOOKUP(F18, Aircraft!A$2:C$99, 3, FALSE) -> S | D18: =IF(ISNA(C18), "", C18) -> S | E18: =IF(ISNA(B18), "", B18) -> PA28 | F18: GBNNY | G18: Kingshott | H18: =IF(UPPER(G18)<>"SELF",IF(G18<>"", "PUT", ""),"P1") -> PUT | I18: EGKA | J18: EGKA | K18: 0.59375 | L18: 0.63194444 | M18: =IF(AND(H18="P1", D18="S"), L18-K18, 0) -> 0 | N18: =IF(AND(H18="PUT", D18="S"), L18-K18, 0) -> 0.038194444 | U18: 0.6 | X18: =SUM(M18:S18) -> 0.038194444 | Y18: Ex 19a, Signed
A19: 35876 | B19: =VLOOKUP(F19, Aircraft!A$2:C$99, 2, FALSE) -> PA28 | C19: =VLOOKUP(F19, Aircraft!A$2:C$99, 3, FALSE) -> S | D19: =IF(ISNA(C19), "", C19) -> S | E19: =IF(ISNA(B19), "", B19) -> PA28 | F19: GRSKR | G19: Kingshott | H19: =IF(UPPER(G19)<>"SELF",IF(G19<>"", "PUT", ""),"P1") -> PUT | I19: EGKA | J19: EGKA | K19: 0.5 | L19: 0.54166667 | M19: =IF(AND(H19="P1", D19="S"), L19-K19, 0) -> 0 | N19: =IF(AND(H19="PUT", D19="S"), L19-K19, 0) -> 0.041666667 | X19: =SUM(M19:S19) -> 0.041666667 | Y19: Revision
A20: 35882 | B20: =VLOOKUP(F20, Aircraft!A$2:C$99, 2, FALSE) -> PA28 | C20: =VLOOKUP(F20, Aircraft!A$2:C$99, 3, FALSE) -> S | D20: =IF(ISNA(C20), "", C20) -> S | E20: =IF(ISNA(B20), "", B20) -> PA28 | F20: GBOTN | G20: Kingshott | H20: =IF(UPPER(G20)<>"SELF",IF(G20<>"", "PUT", ""),"P1") -> PUT | I20: EGKA | J20: EGKA | K20: 0.50347222 | L20: 0.54513889 | M20: =IF(AND(H20="P1", D20="S"), L20-K20, 0) -> 0 | N20: =IF(AND(H20="PUT", D20="S"), L20-K20, 0) -> 0.041666667 | X20: =SUM(M20:S20) -> 0.041666667 | Y20: Ex10b2 - Stalling(0.5) - Signed
A21: 35883 | B21: =VLOOKUP(F21, Aircraft!A$2:C$99, 2, FALSE) -> PA28 | C21: =VLOOKUP(F21, Aircraft!A$2:C$99, 3, FALSE) -> S | D21: =IF(ISNA(C21), "", C21) -> S | E21: =IF(ISNA(B21), "", B21) -> PA28 | F21: GBNNY | G21: Kingshott | H21: =IF(UPPER(G21)<>"SELF",IF(G21<>"", "PUT", ""),"P1") -> PUT | I21: EGKA | J21: EGKA | K21: 0.73958333 | L21: 0.77777778 | M21: =IF(AND(H21="P1", D21="S"), L21-K21, 0) -> 0 | N21: =IF(AND(H21="PUT", D21="S"), L21-K21, 0) -> 0.038194444 | U21: 0.7 | X21: =SUM(M21:S21) -> 0.038194444 | Y21: Ex 19 - Signed
A22: 35892 | B22: =VLOOKUP(F22, Aircraft!A$2:C$99, 2, FALSE) -> PA28 | C22: =VLOOKUP(F22, Aircraft!A$2:C$99, 3, FALSE) -> S | D22: =IF(ISNA(C22), "", C22) -> S | E22: =IF(ISNA(B22), "", B22) -> PA28 | F22: GBNNY | G22: Kingshott | H22: =IF(UPPER(G22)<>"SELF",IF(G22<>"", "PUT", ""),"P1") -> PUT | I22: EGKA | J22: EGKA | K22: 0.63194444 | L22: 0.67013889 | M22: =IF(AND(H22="P1", D22="S"), L22-K22, 0) -> 0 | N22: =IF(AND(H22="PUT", D22="S"), L22-K22, 0) -> 0.038194444 | X22: =SUM(M22:S22) -> 0.038194444 | Y22: Ex12, 13
A23: 35938 | B23: =VLOOKUP(F23, Aircraft!A$2:C$99, 2, FALSE) -> PA28 | C23: =VLOOKUP(F23, Aircraft!A$2:C$99, 3, FALSE) -> S | D23: =IF(ISNA(C23), "", C23) -> S | E23: =IF(ISNA(B23), "", B23) -> PA28 | F23: GBOKB | G23: Kingshott | H23: =IF(UPPER(G23)<>"SELF",IF(G23<>"", "PUT", ""),"P1") -> PUT | I23: EGKA | J23: EGKA | K23: 0.58333333 | L23: 0.62152778 | M23: =IF(AND(H23="P1", D23="S"), L23-K23, 0) -> 0 | N23: =IF(AND(H23="PUT", D23="S"), L23-K23, 0) -> 0.038194444 | X23: =SUM(M23:S23) -> 0.038194444 | Y23: Revision
A24: 35939 | B24: =VLOOKUP(F24, Aircraft!A$2:C$99, 2, FALSE) -> PA28 | C24: =VLOOKUP(F24, Aircraft!A$2:C$99, 3, FALSE) -> S | D24: =IF(ISNA(C24), "", C24) -> S | E24: =IF(ISNA(B24), "", B24) -> PA28 | F24: GBIEY | G24: Kingshott | H24: =IF(UPPER(G24)<>"SELF",IF(G24<>"", "PUT", ""),"P1") -> PUT | I24: EGKA | J24: EGKA | K24: 0.59027778 | L24: 0.625 | M24: =IF(AND(H24="P1", D24="S"), L24-K24, 0) -> 0 | N24: =IF(AND(H24="PUT", D24="S"), L24-K24, 0) -> 0.034722222 | X24: =SUM(M24:S24) -> 0.034722222 | Y24: Revision
A25: 35962 | B25: =VLOOKUP(F25, Aircraft!A$2:C$99, 2, FALSE) -> PA28 | C25: =VLOOKUP(F25, Aircraft!A$2:C$99, 3, FALSE) -> S | D25: =IF(ISNA(C25), "", C25) -> S | E25: =IF(ISNA(B25), "", B25) -> PA28 | F25: GBOTN | G25: Kingshott | H25: =IF(UPPER(G25)<>"SELF",IF(G25<>"", "PUT", ""),"P1") -> PUT | I25: EGKA | J25: EGKA | K25: 0.45486111 | L25: 0.48958333 | M25: =IF(AND(H25="P1", D25="S"), L25-K25, 0) -> 0 | N25: =IF(AND(H25="PUT", D25="S"), L25-K25, 0) -> 0.034722222 | X25: =SUM(M25:S25) -> 0.034722222 | Y25: Revision
A26: 35980 | B26: =VLOOKUP(F26, Aircraft!A$2:C$99, 2, FALSE) -> PA28 | C26: =VLOOKUP(F26, Aircraft!A$2:C$99, 3, FALSE) -> S | D26: =IF(ISNA(C26), "", C26) -> S | E26: =IF(ISNA(B26), "", B26) -> PA28 | F26: GBOJZ | G26: Herlihy | H26: =IF(UPPER(G26)<>"SELF",IF(G26<>"", "PUT", ""),"P1") -> PUT | I26: EGKA | J26: EGKA | K26: 0.70486111 | L26: 0.75 | M26: =IF(AND(H26="P1", D26="S"), L26-K26, 0) -> 0 | N26: =IF(AND(H26="PUT", D26="S"), L26-K26, 0) -> 0.045138889 | X26: =SUM(M26:S26) -> 0.045138889 | Y26: Ex 12, 13, 6+1, Efato, Flapless
A27: 35993 | B27: =VLOOKUP(F27, Aircraft!A$2:C$99, 2, FALSE) -> PA28 | C27: =VLOOKUP(F27, Aircraft!A$2:C$99, 3, FALSE) -> S | D27: =IF(ISNA(C27), "", C27) -> S | E27: =IF(ISNA(B27), "", B27) -> PA28 | F27: GBOJZ | G27: Kingshott | H27: =IF(UPPER(G27)<>"SELF",IF(G27<>"", "PUT", ""),"P1") -> PUT | I27: EGKA | J27: EGKA | K27: 0.57986111 | L27: 0.62152778 | M27: =IF(AND(H27="P1", D27="S"), L27-K27, 0) -> 0 | N27: =IF(AND(H27="PUT", D27="S"), L27-K27, 0) -> 0.041666667 | X27: =SUM(M27:S27) -> 0.041666667 | Y27: Ex 12, 13, 6+1
A28: 35994 | B28: =VLOOKUP(F28, Aircraft!A$2:C$99, 2, FALSE) -> PA28 | C28: =VLOOKUP(F28, Aircraft!A$2:C$99, 3, FALSE) -> S | D28: =IF(ISNA(C28), "", C28) -> S | E28: =IF(ISNA(B28), "", B28) -> PA28 | F28: GBIEY | G28: Kingshott | H28: =IF(UPPER(G28)<>"SELF",IF(G28<>"", "PUT", ""),"P1") -> PUT | I28: EGKA | J28: EGKA | K28: 0.64930556 | L28: 0.69097222 | M28: =IF(AND(H28="P1", D28="S"), L28-K28, 0) -> 0 | N28: =IF(AND(H28="PUT", D28="S"), L28-K28, 0) -> 0.041666667 | X28: =SUM(M28:S28) -> 0.041666667 | Y28: Ex 12, 13, 6+1
A29: 36018 | B29: =VLOOKUP(F29, Aircraft!A$2:C$99, 2, FALSE) -> PA28 | C29: =VLOOKUP(F29, Aircraft!A$2:C$99, 3, FALSE) -> S | D29: =IF(ISNA(C29), "", C29) -> S | E29: =IF(ISNA(B29), "", B29) -> PA28 | F29: GBOKB | G29: Kingshott | H29: =IF(UPPER(G29)<>"SELF",IF(G29<>"", "PUT", ""),"P1") -> PUT | I29: EGKA | J29: EGKA | K29: 0.51736111 | L29: 0.55902778 | M29: =IF(AND(H29="P1", D29="S"), L29-K29, 0) -> 0 | N29: =IF(AND(H29="PUT", D29="S"), L29-K29, 0) -> 0.041666667 | X29: =SUM(M29:S29) -> 0.041666667 | Y29: Ex 12, 13, 6+2
A30: 36126 | B30: =VLOOKUP(F30, Aircraft!A$2:C$99, 2, FALSE) -> PA28 | C30: =VLOOKUP(F30, Aircraft!A$2:C$99, 3, FALSE) -> S | D30: =IF(ISNA(C30), "", C30) -> S | E30: =IF(ISNA(B30), "", B30) -> PA28 | F30: GBPDU | G30: Herlihy | H30: =IF(UPPER(G30)<>"SELF",IF(G30<>"", "PUT", ""),"P1") -> PUT | I30: EGKA | J30: EGKA | K30: 0.4375 | L30: 0.48263889 | M30: =IF(AND(H30="P1", D30="S"), L30-K30, 0) -> 0 | N30: =IF(AND(H30="PUT", D30="S"), L30-K30, 0) -> 0.045138889 | X30: =SUM(M30:S30) -> 0.045138889 | Y30: Ex 10a (Signed), Ex12, 13 3+1
A31: 36126 | B31: =VLOOKUP(F31, Aircraft!A$2:C$99, 2, FALSE) -> PA28 | C31: =VLOOKUP(F31, Aircraft!A$2:C$99, 3, FALSE) -> S | D31: =IF(ISNA(C31), "", C31) -> S | E31: =IF(ISNA(B31), "", B31) -> PA28 | F31: GBPDU | G31: Kingshott | H31: =IF(UPPER(G31)<>"SELF",IF(G31<>"", "PUT", ""),"P1") -> PUT | I31: EGKA | J31: EGKA | K31: 0.61458333 | L31: 0.63888889 | M31: =IF(AND(H31="P1", D31="S"), L31-K31, 0) -> 0 | N31: =IF(AND(H31="PUT", D31="S"), L31-K31, 0) -> 0.024305556 | X31: =SUM(M31:S31) -> 0.024305556 | Y31: Ex 12, 13 2+1
A32: 36126 | B32: =VLOOKUP(F32, Aircraft!A$2:C$99, 2, FALSE) -> PA28 | C32: =VLOOKUP(F32, Aircraft!A$2:C$99, 3, FALSE) -> S | D32: =IF(ISNA(C32), "", C32) -> S | E32: =IF(ISNA(B32), "", B32) -> PA28 | F32: GBPDU | G32: N Hill | H32: =IF(UPPER(G32)<>"SELF",IF(G32<>"", "PUT", ""),"P1") -> PUT | I32: EGKA | J32: EGKA | K32: 0.64930556 | L32: 0.67361111 | M32: =IF(AND(H32="P1", D32="S"), L32-K32, 0) -> 0 | N32: =IF(AND(H32="PUT", D32="S"), L32-K32, 0) -> 0.024305556 | X32: =SUM(M32:S32) -> 0.024305556 | Y32: Ex 12, 13, 1+1
A33: 36126 | B33: =VLOOKUP(F33, Aircraft!A$2:C$99, 2, FALSE) -> PA28 | C33: =VLOOKUP(F33, Aircraft!A$2:C$99, 3, FALSE) -> S | D33: =IF(ISNA(C33), "", C33) -> S | E33: =IF(ISNA(B33), "", B33) -> PA28 | F33: GBPDU | G33: Self | H33: =IF(UPPER(G33)<>"SELF",IF(G33<>"", "PUT", ""),"P1") -> P1 | I33: EGKA | J33: EGKA | K33: 0.67708333 | L33: 0.68402778 | M33: =IF(AND(H33="P1", D33="S"), L33-K33, 0) -> 0.0069444444 | N33: =IF(AND(H33="PUT", D33="S"), L33-K33, 0) -> 0 | X33: =SUM(M33:S33) -> 0.0069444444 | Y33: Ex 14 - First Solo!
... A66: 36424 | B66: =VLOOKUP(F66, Aircraft!A$2:C$99, 2, FALSE) -> PA28 | C66: =VLOOKUP(F66, Aircraft!A$2:C$99, 3, FALSE) -> S | D66: =IF(ISNA(C66), "", C66) -> S | E66: =IF(ISNA(B66), "", B66) -> PA28 | F66: GBOJZ | G66: Self | H66: =IF(UPPER(G66)<>"SELF",IF(G66<>"", "PUT", ""),"P1") -> P1 | I66: EGKA | J66: EGHR | K66: 0.52430556 | L66: 0.54513889 | M66: =IF(AND(H66="P1", D66="S"), L66-K66, 0) -> 0.020833333 | N66: =IF(AND(H66="PUT", D66="S"), L66-K66, 0) -> 0 | X66: =SUM(M66:S66) -> 0.020833333 | Y66: Solo Away
A67: 36424 | B67: =VLOOKUP(F67, Aircraft!A$2:C$99, 2, FALSE) -> PA28 | C67: =VLOOKUP(F67, Aircraft!A$2:C$99, 3, FALSE) -> S | D67: =IF(ISNA(C67), "", C67) -> S | E67: =IF(ISNA(B67), "", B67) -> PA28 | F67: GBOJZ | G67: Self | H67: =IF(UPPER(G67)<>"SELF",IF(G67<>"", "PUT", ""),"P1") -> P1 | I67: EGHR | J67: EGKA | K67: 0.58680556 | L67: 0.6125 | M67: =IF(AND(H67="P1", D67="S"), L67-K67, 0) -> 0.025694444 | N67: =IF(AND(H67="PUT", D67="S"), L67-K67, 0) -> 0 | X67: =SUM(M67:S67) -> 0.025694444
A68: 36435 | B68: =VLOOKUP(F68, Aircraft!A$2:C$99, 2, FALSE) -> PA28 | C68: =VLOOKUP(F68, Aircraft!A$2:C$99, 3, FALSE) -> S | D68: =IF(ISNA(C68), "", C68) -> S | E68: =IF(ISNA(B68), "", B68) -> PA28 | F68: GBPDU | G68: Self | H68: =IF(UPPER(G68)<>"SELF",IF(G68<>"", "PUT", ""),"P1") -> P1 | I68: EGKA | J68: EGLS | K68: 0.60416667 | L68: 0.64236111 | M68: =IF(AND(H68="P1", D68="S"), L68-K68, 0) -> 0.038194444 | N68: =IF(AND(H68="PUT", D68="S"), L68-K68, 0) -> 0 | X68: =SUM(M68:S68) -> 0.038194444
A69: 36435 | B69: =VLOOKUP(F69, Aircraft!A$2:C$99, 2, FALSE) -> PA28 | C69: =VLOOKUP(F69, Aircraft!A$2:C$99, 3, FALSE) -> S | D69: =IF(ISNA(C69), "", C69) -> S | E69: =IF(ISNA(B69), "", B69) -> PA28 | F69: GBPDU | G69: Self | H69: =IF(UPPER(G69)<>"SELF",IF(G69<>"", "PUT", ""),"P1") -> P1 | I69: EGLS | J69: EGKA | K69: 0.66319444 | L69: 0.69791667 | M69: =IF(AND(H69="P1", D69="S"), L69-K69, 0) -> 0.034722222 | N69: =IF(AND(H69="PUT", D69="S"), L69-K69, 0) -> 0 | X69: =SUM(M69:S69) -> 0.034722222
A71: 36533 | B71: =VLOOKUP(F71, Aircraft!A$2:C$99, 2, FALSE) -> PA28 | C71: =VLOOKUP(F71, Aircraft!A$2:C$99, 3, FALSE) -> S | D71: =IF(ISNA(C71), "", C71) -> S | E71: =IF(ISNA(B71), "", B71) -> PA28 | F71: GBOJZ | G71: Vickers | H71: =IF(UPPER(G71)<>"SELF",IF(G71<>"", "PUT", ""),"P1") -> PUT | I71: EGKA | J71: EGKA | K71: 0.64236111 | L71: 0.6875 | M71: =IF(AND(H71="P1", D71="S"), L71-K71, 0) -> 0 | N71: =IF(AND(H71="PUT", D71="S"), L71-K71, 0) -> 0.045138889 | X71: =SUM(M71:S71) -> 0.045138889 | Y71: Ex 15, Steep turns, Ex 10b PFL, Ex 16 1+1, Stalling - Signed
A72: 36548 | B72: =VLOOKUP(F72, Aircraft!A$2:C$99, 2, FALSE) -> PA28 | C72: =VLOOKUP(F72, Aircraft!A$2:C$99, 3, FALSE) -> S | D72: =IF(ISNA(C72), "", C72) -> S | E72: =IF(ISNA(B72), "", B72) -> PA28 | F72: GEKKL | G72: Mitchell | H72: =IF(UPPER(G72)<>"SELF",IF(G72<>"", "PUT", ""),"P1") -> PUT | I72: EGKA | J72: EGKA | K72: 0.57152778 | L72: 0.61319444 | M72: =IF(AND(H72="P1", D72="S"), L72-K72, 0) -> 0 | N72: =IF(AND(H72="PUT", D72="S"), L72-K72, 0) -> 0.041666667 | X72: =SUM(M72:S72) -> 0.041666667 | Y72: Ex 15, Ex 10, Stalls - Signed
A73: 36558 | B73: =VLOOKUP(F73, Aircraft!A$2:C$99, 2, FALSE) -> PA28 | C73: =VLOOKUP(F73, Aircraft!A$2:C$99, 3, FALSE) -> S | D73: =IF(ISNA(C73), "", C73) -> S | E73: =IF(ISNA(B73), "", B73) -> PA28 | F73: GEKKL | G73: Vickers | H73: =IF(UPPER(G73)<>"SELF",IF(G73<>"", "PUT", ""),"P1") -> PUT | I73: EGKA | J73: EGMD | K73: 0.4375 | L73: 0.46875 | M73: =IF(AND(H73="P1", D73="S"), L73-K73, 0) -> 0 | N73: =IF(AND(H73="PUT", D73="S"), L73-K73, 0) -> 0.03125 | X73: =SUM(M73:S73) -> 0.03125 | Y73: Ex 18c, Pre Qual with Diversion
A74: 36558 | B74: =VLOOKUP(F74, Aircraft!A$2:C$99, 2, FALSE) -> PA28 | C74: =VLOOKUP(F74, Aircraft!A$2:C$99, 3, FALSE) -> S | D74: =IF(ISNA(C74), "", C74) -> S | E74: =IF(ISNA(B74), "", B74) -> PA28 | F74: GEKKL | G74: Vickers | H74: =IF(UPPER(G74)<>"SELF",IF(G74<>"", "PUT", ""),"P1") -> PUT | I74: EGMD | J74: EGKB | K74: 0.47569444 | L74: 0.50694444 | M74: =IF(AND(H74="P1", D74="S"), L74-K74, 0) -> 0 | N74: =IF(AND(H74="PUT", D74="S"), L74-K74, 0) -> 0.03125 | X74: =SUM(M74:S74) -> 0.03125
A75: 36558 | B75: =VLOOKUP(F75, Aircraft!A$2:C$99, 2, FALSE) -> PA28 | C75: =VLOOKUP(F75, Aircraft!A$2:C$99, 3, FALSE) -> S | D75: =IF(ISNA(C75), "", C75) -> S | E75: =IF(ISNA(B75), "", B75) -> PA28 | F75: GEKKL | G75: Vickers | H75: =IF(UPPER(G75)<>"SELF",IF(G75<>"", "PUT", ""),"P1") -> PUT | I75: EGKB | J75: EGKA | K75: 0.52777778 | L75: 0.55902778 | M75: =IF(AND(H75="P1", D75="S"), L75-K75, 0) -> 0 | N75: =IF(AND(H75="PUT", D75="S"), L75-K75, 0) -> 0.03125 | X75: =SUM(M75:S75) -> 0.03125
...

Sheet By Instructor
A3: Sum of Flight Time | D3: Captain
A4: Engines | B4: Ttype | C4: Reg | D4: Self | E4: Marshall | F4: Terry | G4: Kingshott | H4: Chapman | I4: McKinnon | J4: Vickers | K4: Chowen | L4: Gould | M4: Rabson | N4: Brownie | O4: Frampton | P4: Powell | Q4: Gwilliam | R4: East | S4: Wilton | T4: Westwood | U4: Whitehead | V4: Batt | W4: Herlihy | X4: Harling | Y4: Rutherford | Z4: Mitchell | AA4: Ilett | AB4: A Hill | AC4: N Hill | AD4: Grand Total
A5: S | B5: PA28 | D5: 7.6145833 | F5: 0.57986111 | G5: 0.81388889 | H5: 0.054166667 | I5: 0.51388889 | J5: 0.8125 | K5: 0.076388889 | M5: 0.20486111 | N5: 0.18472222 | P5: 0.17361111 | Q5: 0.069444444 | V5: 0.09375 | W5: 0.090277778 | X5: 0.076388889 | Y5: 0.041666667 | Z5: 0.041666667 | AA5: 0.041666667 | AC5: 0.024305556 | AD5: 11.507639
B6: PA28-235 | D6: 1.7833333 | I6: 0.28819444 | AD6: 2.0715278
B7: DHC-1 | D7: 0.34097222 | H7: 1.0298611 | I7: 0.045138889 | J7: 0.041666667 | T7: 0.10069444 | AD7: 1.5583333
B8: Archer-III | D8: 1.0527778 | I8: 0.038194444 | AD8: 1.0909722
B9: PA28R | D9: 0.14861111 | E9: 0.40486111 | M9: 0.080555556 | O9: 0.090277778 | AD9: 0.72430556
B10: PA38 | D10: 0.076388889 | F10: 0.47569444 | AD10: 0.55208333
B11: PA-32RT | D11: 0.45972222 | I11: 0.059027778 | AD11: 0.51875
B12: C152 | G12: 0.31944444 | AD12: 0.31944444
B13: T67C | F13: 0.125 | AD13: 0.125
B14: AA-5 | D14: 0.074305556 | I14: 0.045138889 | AD14: 0.11944444
B15: JP5A | AB15: 0.038194444 | AD15: 0.038194444
B16: C172 | F16: 0.034722222 | AD16: 0.034722222
B17: EXTRA | T17: 0.027777778 | AD17: 0.027777778
A18: S Total | D18: 11.550694 | E18: 0.40486111 | F18: 1.2152778 | G18: 1.1333333 | H18: 1.0840278 | I18: 0.98958333 | J18: 0.85416667 | K18: 0.076388889 | M18: 0.28541667 | N18: 0.18472222 | O18: 0.090277778 | P18: 0.17361111 | Q18: 0.069444444 | T18: 0.12847222 | V18: 0.09375 | W18: 0.090277778 | X18: 0.076388889 | Y18: 0.041666667 | Z18: 0.041666667 | AA18: 0.041666667 | AB18: 0.038194444 | AC18: 0.024305556 | AD18: 18.688194
A19: T | B19: PA34 | D19: 2.8083333 | E19: 1.4861111 | K19: 0.36458333 | L19: 0.40902778 | O19: 0.09375 | Q19: 0.090277778 | R19: 0.14236111 | U19: 0.10486111 | AD19: 5.4993056
B20: BE76 | D20: 1.0465278 | S20: 0.13888889 | AD20: 1.1854167
B21: PA23 | D21: 1.1520833 | F21: 0.024305556 | AD21: 1.1763889
A22: T Total | D22: 5.0069444 | E22: 1.4861111 | F22: 0.024305556 | K22: 0.36458333 | L22: 0.40902778 | O22: 0.09375 | Q22: 0.090277778 | R22: 0.14236111 | S22: 0.13888889 | U22: 0.10486111 | AD22: 7.8611111
A23: Grand Total | D23: 16.557639 | E23: 1.8909722 | F23: 1.2395833 | G23: 1.1333333 | H23: 1.0840278 | I23: 0.98958333 | J23: 0.85416667 | K23: 0.44097222 | L23: 0.40902778 | M23: 0.28541667 | N23: 0.18472222 | O23: 0.18402778 | P23: 0.17361111 | Q23: 0.15972222 | R23: 0.14236111 | S23: 0.13888889 | T23: 0.12847222 | U23: 0.10486111 | V23: 0.09375 | W23: 0.090277778 | X23: 0.076388889 | Y23: 0.041666667 | Z23: 0.041666667 | AA23: 0.041666667 | AB23: 0.038194444 | AC23: 0.024305556 | AD23: 26.549306

Sheet By Type
A3: Count of Ttype | C3: Ttype
A4: Engines | B4: Reg | C4: PA28 | D4: PA34 | E4: DHC-1 | F4: PA28-235 | G4: BE76 | H4: Archer-III | I4: PA23 | J4: PA28R | K4: PA38 | L4: PA-32RT | M4: C152 | N4: T67C | O4: AA-5 | P4: EXTRA | Q4: C172 | R4: JP5A | S4: Grand Total
A5: S | B5: GEKKL | C5: 72 | S5: 72
B6: GBZGA | E6: 47 | S6: 47
B7: GAWSM | F7: 36 | S7: 36
B8: GBOKB | C8: 32 | S8: 32
B9: GBOJZ | C9: 30 | S9: 30
B10: GBPDU | C10: 30 | S10: 30
B11: GBTDV | C11: 20 | S11: 20
B12: GBZHV | H12: 16 | S12: 16
B13: GBSZT | C13: 15 | S13: 15
B14: GBMOE | J14: 13 | S14: 13
B15: GBYMD | K15: 11 | S15: 11
B16: GOPUK | C16: 11 | S16: 11
B17: GTFYN | L17: 10 | S17: 10
B18: GBNEL | C18: 10 | S18: 10
B19: GBUIK | C19: 8 | S19: 8
B20: GRSKR | C20: 7 | S20: 7
B21: GBUJP | C21: 7 | S21: 7
B22: GBZHK | H22: 6 | S22: 6
B23: GBOTN | C23: 5 | S23: 5
B24: GBUJO | C24: 5 | S24: 5
B25: GBNNY | C25: 5 | S25: 5
B26: GBIEY | C26: 4 | S26: 4
B27: GBASW | C27: 4 | S27: 4
B28: GBPTF | M28: 3 | S28: 3
B29: GBOCL | N29: 3 | S29: 3
B30: GBBCZ | O30: 3 | S30: 3
B31: GLSMI | M31: 3 | S31: 3
B32: GWARY | C32: 2 | S32: 2
B33: N8351W | C33: 2 | S33: 2
B34: GSARA | C34: 2 | S34: 2
B35: GSACZ | C35: 1 | S35: 1
B36: N8391S | C36: 1 | S36: 1
B37: GBOIN | M37: 1 | S37: 1
B38: GRKSR | C38: 1 | S38: 1
B39: GIIEX | P39: 1 | S39: 1
B40: GBCAH | E40: 1 | S40: 1
B41: GBMTS | Q41: 1 | S41: 1
B42: GEVTO | C42: 1 | S42: 1
...

Sheet Aircraft
A1: Reg | B1: Type Number | C1: Type | D1: # Flights
A2: GEKKL | B2: PA28 | C2: S | D2: =COUNTIF('Log Book'!F:F, A2) -> 72
A3: GHCSL | B3: PA34 | C3: T | D3: =COUNTIF('Log Book'!F:F, A3) -> 51
A4: GBZGA | B4: DHC-1 | C4: S | D4: =COUNTIF('Log Book'!F:F, A4) -> 47
A5: GAWSM | B5: PA28-235 | C5: S | D5: =COUNTIF('Log Book'!F:F, A5) -> 36
A6: GBOJZ | B6: PA28 | C6: S | D6: =COUNTIF('Log Book'!F:F, A6) -> 30
A7: GBPDU | B7: PA28 | C7: S | D7: =COUNTIF('Log Book'!F:F, A7) -> 30
A8: GLORD | B8: PA34 | C8: T | D8: =COUNTIF('Log Book'!F:F, A8) -> 28
A9: GGDMW | B9: BE76 | C9: T | D9: =COUNTIF('Log Book'!F:F, A9) -> 27
A10: GBOKB | B10: PA28 | C10: S | D10: =COUNTIF('Log Book'!F:F, A10) -> 32
A11: GBTDV | B11: PA28 | C11: S | D11: =COUNTIF('Log Book'!F:F, A11) -> 20
A12: GBCCE | B12: PA23 | C12: T | D12: =COUNTIF('Log Book'!F:F, A12) -> 18
A13: GBZHV | B13: Archer-III | C13: S | D13: =COUNTIF('Log Book'!F:F, A13) -> 16
... A49: GEVTO | B49: PA28 | C49: S | D49: =COUNTIF('Log Book'!F:F, A49) -> 1
A50: GBUIY | B50: PA28 | C50: S | D50: 1
A51: GELZY | B51: PA28 | C51: S | D51: 1

Sheet By Instructor (2)
A3: Count of To | B3: Engines
A4: To | B4: S | C4: SIM | D4: T | E4: Grand Total
A5: EGKA | B5: 313 | D5: 60 | E5: 373
A6: EGHI | B6: 17 | D6: 32 | E6: 49
A7: EGHR | B7: 21 | E7: 21
A8: EGMD | B8: 12 | D8: 5 | E8: 17
A9: SIM | C9: 13 | E9: 13
A10: EGBW | B10: 8 | D10: 3 | E10: 11
A11: EIWT | B11: 2 | D11: 7 | E11: 9
A12: LFRG | B12: 2 | D12: 7 | E12: 9
A13: LFAT | B13: 3 | D13: 4 | E13: 7
A14: EGFF | B14: 3 | D14: 4 | E14: 7
A15: EGNT | B15: 3 | D15: 3 | E15: 6
A16: EGHA | B16: 4 | E16: 4
A17: EGUS | D17: 3 | E17: 3
A18: EGLK | B18: 3 | E18: 3
A19: EGHN | B19: 3 | E19: 3
A20: EGKB | B20: 3 | E20: 3
A21: EGHJ | B21: 3 | E21: 3
A22: EGCV | B22: 1 | D22: 2 | E22: 3
A23: EGLS | B23: 3 | E23: 3
A24: EGTF | B24: 2 | E24: 2
A25: EGLM | B25: 2 | E25: 2
A26: EGBE | B26: 1 | D26: 1 | E26: 2
A27: EGHH | B27: 2 | E27: 2
A28: LFAC | D28: 2 | E28: 2
A29: EGMC | B29: 2 | E29: 2
A30: EGGD | C30: 1 | D30: 1 | E30: 2
A31: EBOS | B31: 2 | E31: 2
A32: KTEB | B32: 2 | E32: 2
A33: EGSR | B33: 2 | E33: 2
A34: LFOP | B34: 1 | D34: 1 | E34: 2
A35: EGBS | B35: 2 | E35: 2
A36: LFLP | D36: 1 | E36: 1
A37: LFBK | B37: 1 | E37: 1
A38: EGBJ | D38: 1 | E38: 1
A39: KMMV | B39: 1 | E39: 1
A40: LFOQ | B40: 1 | E40: 1
A41: LFOD | D41: 1 | E41: 1
A42: EGSX | B42: 1 | E42: 1
...

Sheet Sheet1
A1: Code | B1: Aiport | C1: Where
A2: EGAA | B2: Belfast International Airport | C2: Belfast, Northern Ireland
A3: EGAB | B3: Enniskillen/St Angelo Airport | C3: Enniskillen, Northern Ireland
A4: EGAC | B4: George Best Belfast City Airport | C4: Belfast, Northern Ireland
A5: EGAD | B5: Newtownards Airport | C5: Newtownards, Northern Ireland
A6: EGAE | B6: City of Derry Airport | C6: Derry, Northern Ireland
A7: EGBB | B7: Birmingham International Airport | C7: Birmingham, England
A8: EGBC | B8: Cheltenham Racecourse Heliport | C8: Cheltenham Racecourse, England
A9: EGBD | B9: Derby Airfield | C9: Derby, England
A10: EGBE | B10: Coventry Airport | C10: Coventry, England
A11: EGBG | B11: Leicester Airport | C11: Leicester, England
A12: EGBJ | B12: Gloucestershire Airport | C12: Staverton, England
... A669: LFYS | B669: Sainte-Léocadie Airport | C669: Sainte-Léocadie
A670: EBAM | B670: Amougies airfield
A671: EBAW | B671: Antwerp International Airport | C671: Antwerp / Deurne
A672: EBBE | B672: Beauvechain Air Base | C672: Beauvechain
A673: EBBL | B673: Kleine Brogel Air Base | C673: Kleine Brogel
A674: EBBR | B674: Brussels Airport | C674: Brussels / Zaventem
A675: EBBT | B675: Brasschaat Airfield | C675: Brasschaat
A676: EBBX | B676: Jehonville Air Base | C676: Bertrix
A677: EBBY | B677: Baisy-Thy Ulmodrome
A678: EBBZ | B678: Buzet Ulmodrome
A679: EBCI | B679: Brussels South Charleroi Airport | C679: Charleroi
A680: EBCF | B680: Cerfontaine Airfield | C680: Cerfontaine
A681: EBCV | B681: Chievres AB (U.S. Air Force) | C681: Chievres
A682: EBFN | B682: Koksijde AB | C682: Koksijde
A683: EBFS | B683: Florennes Air Base | C683: Florennes
A684: EBGB | B684: Grimbergen Airfield | C684: Grimbergen
A685: EBHN | B685: Hoevenen Airfield | C685: Hoevenen
A686: EBKH | B686: Balen-Keiheuvel Airport | C686: Balen-Keiheuvel
A687: EBKT | B687: Kortrijk-Wevelgem International Airport | C687: Kortrijk / Wevelgem
A688: EBLG | B688: Liege Airport | C688: Liège
A689: EBLE | B689: Beverlo Air Base | C689: Leopoldsburg
A690: EBMB | B690: Melsbroek Air Base | C690: Brussels
... A706: EBZW | B706: Zwartberg Airfield | C706: Genk
